<?xml version="1.0" ?>
<!-- =================================================================================== -->
<!-- |    This document was autogenerated by xacro from src/akm_bringup/urdf/model.xacro | -->
<!-- |    EDITING THIS FILE BY HAND IS NOT RECOMMENDED                                 | -->
<!-- =================================================================================== -->
<robot name="demo">
  <!-- COLOUR -->
  <material name="silver">
    <color rgba="0.1 0.1 0.1 0.5"/>
  </material>
  <material name="blue">
    <color rgba="0.1 0.1 1.0 0.5"/>
  </material>
  <material name="green">
    <color rgba="0.1 1.0 0.1 0.5"/>
  </material>
  <material name="yellow">
    <color rgba="1.0 1.0 0.1 1.0"/>
  </material>
  <material name="red">
    <color rgba="1.0 0.1 0.1 0.5"/>
  </material>
  <material name="black">
    <color rgba="0.0 0.0 0.0 0.5"/>
  </material>
  <!--  Base Link  -->
  <link name="base_link"/>
  <!--  Chassis  -->
  <joint name="base_link_joint" type="fixed">
    <origin rpy="0 0 0" xyz="0.16 0 0.05"/>
    <parent link="base_link"/>
    <child link="chassis"/>
  </joint>
  <link name="chassis">
    <inertial>
      <mass value="3.5"/>
      <origin rpy=" 0 0 0" xyz="0 0 0"/>
      <inertia ixx="0.010179166666666668" ixy="0" ixz="0" iyy="0.07075833333333333" iyz="0" izz="0.07947916666666666"/>
    </inertial>
    <collision name="collision">
      <origin rpy=" 0 0 0" xyz="0 0 0"/>
      <geometry>
        <box size="0.49 0.18 0.05"/>
      </geometry>
    </collision>
    <visual>
      <origin rpy=" 0 0 0" xyz="0 0 0"/>
      <geometry>
        <box size="0.49 0.18 0.05"/>
      </geometry>
      <material name="yellow"/>
    </visual>
  </link>
  <gazebo reference="chassis">
    <material>Gazebo/Yellow</material>
  </gazebo>
  <!--  Steering wheel  -->
  <joint name="steering_wheel_joint" type="continuous">
    <origin rpy="0 0 0" xyz="-0.16 0 0.035"/>
    <parent link="chassis"/>
    <child link="steering_wheel"/>
    <axis xyz="1 0 0"/>
    <limit effort="10000000" lower="-9.250245035569947" upper="9.250245035569947" velocity="1000000"/>
  </joint>
  <link name="steering_wheel">
    <inertial>
      <mass value="0.1"/>
      <inertia ixx="1.6666666666666669e-06" ixy="0" ixz="0" iyy="1.6666666666666669e-06" iyz="0" izz="1.6666666666666669e-06"/>
    </inertial>
    <collision name="collision">
      <geometry>
        <box size="0.01 0.01 0.01"/>
      </geometry>
    </collision>
    <visual>
      <origin rpy=" 0 0 0" xyz="0 0 0"/>
      <geometry>
        <box size="0.01 0.01 0.01"/>
      </geometry>
      <material name="yellow"/>
    </visual>
  </link>
  <gazebo reference="steering_wheel">
    <material>Gazebo/Yellow</material>
  </gazebo>
  <link name="left_wheel_front">
    <inertial>
      <mass value="0.2"/>
      <origin rpy="1.5707963267948966 0 0" xyz="0 0.02 0"/>
      <inertia ixx="0.00014541666666666671" ixy="0" ixz="0" iyy="0.00014541666666666671" iyz="0" izz="0.00025000000000000006"/>
    </inertial>
    <collision>
      <origin rpy="1.5707963267948966 0 0 " xyz="0 0.02 0"/>
      <geometry>
        <cylinder length="0.035" radius="0.05"/>
      </geometry>
    </collision>
    <visual>
      <origin rpy="1.5707963267948966 0 3.141592653589793" xyz="0 0.02 0"/>
      <geometry>
        <cylinder length="0.035" radius="0.05"/>
      </geometry>
      <material name="black"/>
    </visual>
  </link>
  <joint name="left_wheel_front_hinge" type="continuous">
    <parent link="left_steering"/>
    <child link="left_wheel_front"/>
    <origin rpy="0 0 0" xyz="0 0.001 0.0"/>
    <axis rpy="0 0 0" xyz="0 1 0"/>
    <limit effort="20" velocity="500"/>
    <joint_properties damping="1e-9" friction="1e-9"/>
  </joint>
  <transmission name="left_wheel_front_transmission" type="SimpleTransmission">
    <type>transmission_interface/SimpleTransmission</type>
    <joint name="left_wheel_front_hinge">
      <hardwareInterface>hardware_interface/EffortJointInterface</hardwareInterface>
    </joint>
    <actuator name="left_wheel_front_motor">
      <hardwareInterface>hardware_interface/EffortJointInterface</hardwareInterface>
      <mechanicalReduction>1</mechanicalReduction>
    </actuator>
  </transmission>
  <gazebo reference="left_wheel_front">
    <material>Gazebo/Black</material>
    <mu1>0.9</mu1>
    <mu2>0.9</mu2>
  </gazebo>
  <link name="right_wheel_front">
    <inertial>
      <mass value="0.2"/>
      <origin rpy="1.5707963267948966 0 0" xyz="0 -0.02 0"/>
      <inertia ixx="0.00014541666666666671" ixy="0" ixz="0" iyy="0.00014541666666666671" iyz="0" izz="0.00025000000000000006"/>
    </inertial>
    <collision>
      <origin rpy="1.5707963267948966 0 0 " xyz="0 -0.02 0"/>
      <geometry>
        <cylinder length="0.035" radius="0.05"/>
      </geometry>
    </collision>
    <visual>
      <origin rpy="1.5707963267948966 0 0.0" xyz="0 -0.02 0"/>
      <geometry>
        <cylinder length="0.035" radius="0.05"/>
      </geometry>
      <material name="black"/>
    </visual>
  </link>
  <joint name="right_wheel_front_hinge" type="continuous">
    <parent link="right_steering"/>
    <child link="right_wheel_front"/>
    <origin rpy="0 0 0" xyz="0 -0.001 0.0"/>
    <axis rpy="0 0 0" xyz="0 1 0"/>
    <limit effort="20" velocity="500"/>
    <joint_properties damping="1e-9" friction="1e-9"/>
  </joint>
  <transmission name="right_wheel_front_transmission" type="SimpleTransmission">
    <type>transmission_interface/SimpleTransmission</type>
    <joint name="right_wheel_front_hinge">
      <hardwareInterface>hardware_interface/EffortJointInterface</hardwareInterface>
    </joint>
    <actuator name="right_wheel_front_motor">
      <hardwareInterface>hardware_interface/EffortJointInterface</hardwareInterface>
      <mechanicalReduction>1</mechanicalReduction>
    </actuator>
  </transmission>
  <gazebo reference="right_wheel_front">
    <material>Gazebo/Black</material>
    <mu1>0.9</mu1>
    <mu2>0.9</mu2>
  </gazebo>
  <link name="left_wheel_back">
    <inertial>
      <mass value="0.2"/>
      <origin rpy="1.5707963267948966 0 0" xyz="0 0.021 0"/>
      <inertia ixx="0.00014541666666666671" ixy="0" ixz="0" iyy="0.00014541666666666671" iyz="0" izz="0.00025000000000000006"/>
    </inertial>
    <collision>
      <origin rpy="1.5707963267948966 0 0 " xyz="0 0.021 0"/>
      <geometry>
        <cylinder length="0.035" radius="0.05"/>
      </geometry>
    </collision>
    <visual>
      <origin rpy="1.5707963267948966 0 3.141592653589793" xyz="0 0.021 0"/>
      <geometry>
        <cylinder length="0.035" radius="0.05"/>
      </geometry>
      <material name="black"/>
    </visual>
  </link>
  <joint name="left_wheel_back_hinge" type="continuous">
    <parent link="chassis"/>
    <child link="left_wheel_back"/>
    <origin rpy="0 0 0" xyz="-0.16 0.10275 0.0"/>
    <axis rpy="0 0 0" xyz="0 1 0"/>
    <limit effort="20" velocity="500"/>
    <joint_properties damping="1e-9" friction="1e-9"/>
  </joint>
  <transmission name="left_wheel_back_transmission" type="SimpleTransmission">
    <type>transmission_interface/SimpleTransmission</type>
    <joint name="left_wheel_back_hinge">
      <hardwareInterface>hardware_interface/EffortJointInterface</hardwareInterface>
    </joint>
    <actuator name="left_wheel_back_motor">
      <hardwareInterface>hardware_interface/EffortJointInterface</hardwareInterface>
      <mechanicalReduction>1</mechanicalReduction>
    </actuator>
  </transmission>
  <gazebo reference="left_wheel_back">
    <material>Gazebo/Black</material>
    <mu1>0.9</mu1>
    <mu2>0.9</mu2>
  </gazebo>
  <link name="right_wheel_back">
    <inertial>
      <mass value="0.2"/>
      <origin rpy="1.5707963267948966 0 0" xyz="0 -0.021 0"/>
      <inertia ixx="0.00014541666666666671" ixy="0" ixz="0" iyy="0.00014541666666666671" iyz="0" izz="0.00025000000000000006"/>
    </inertial>
    <collision>
      <origin rpy="1.5707963267948966 0 0 " xyz="0 -0.021 0"/>
      <geometry>
        <cylinder length="0.035" radius="0.05"/>
      </geometry>
    </collision>
    <visual>
      <origin rpy="1.5707963267948966 0 0.0" xyz="0 -0.021 0"/>
      <geometry>
        <cylinder length="0.035" radius="0.05"/>
      </geometry>
      <material name="black"/>
    </visual>
  </link>
  <joint name="right_wheel_back_hinge" type="continuous">
    <parent link="chassis"/>
    <child link="right_wheel_back"/>
    <origin rpy="0 0 0" xyz="-0.16 -0.10275 0.0"/>
    <axis rpy="0 0 0" xyz="0 1 0"/>
    <limit effort="20" velocity="500"/>
    <joint_properties damping="1e-9" friction="1e-9"/>
  </joint>
  <transmission name="right_wheel_back_transmission" type="SimpleTransmission">
    <type>transmission_interface/SimpleTransmission</type>
    <joint name="right_wheel_back_hinge">
      <hardwareInterface>hardware_interface/EffortJointInterface</hardwareInterface>
    </joint>
    <actuator name="right_wheel_back_motor">
      <hardwareInterface>hardware_interface/EffortJointInterface</hardwareInterface>
      <mechanicalReduction>1</mechanicalReduction>
    </actuator>
  </transmission>
  <gazebo reference="right_wheel_back">
    <material>Gazebo/Black</material>
    <mu1>0.9</mu1>
    <mu2>0.9</mu2>
  </gazebo>
  <link name="left_steering">
    <inertial>
      <mass value="0.07"/>
      <origin rpy="0 0 0" xyz="0 0 0"/>
      <inertia ixx="4.666666666666667e-06" ixy="0" ixz="0" iyy="4.666666666666667e-06" iyz="0" izz="4.666666666666667e-06"/>
    </inertial>
    <visual>
      <origin rpy="0 0 0" xyz="0 0 0"/>
      <geometry>
        <sphere radius="0.01"/>
      </geometry>
    </visual>
  </link>
  <gazebo reference="left_steering">
    <material>Gazebo/Grey</material>
  </gazebo>
  <joint name="left_steering_hinge" type="revolute">
    <origin rpy="0 0 0" xyz="0.16 0.10275 0"/>
    <parent link="chassis"/>
    <child link="left_steering"/>
    <axis xyz="0 0 1"/>
    <limit effort="10" lower="-0.5235987755982988" upper="0.5235987755982988" velocity="100"/>
  </joint>
  <transmission name="left_steering_hinge_transmission" type="SimpleTransmission">
    <type>transmission_interface/SimpleTransmission</type>
    <joint name="left_steering_hinge">
      <hardwareInterface>hardware_interface/EffortJointInterface</hardwareInterface>
    </joint>
    <actuator name="left_steering_hinge_motor">
      <hardwareInterface>hardware_interface/EffortJointInterface</hardwareInterface>
      <mechanicalReduction>1</mechanicalReduction>
    </actuator>
  </transmission>
  <link name="right_steering">
    <inertial>
      <mass value="0.07"/>
      <origin rpy="0 0 0" xyz="0 0 0"/>
      <inertia ixx="4.666666666666667e-06" ixy="0" ixz="0" iyy="4.666666666666667e-06" iyz="0" izz="4.666666666666667e-06"/>
    </inertial>
    <visual>
      <origin rpy="0 0 0" xyz="0 0 0"/>
      <geometry>
        <sphere radius="0.01"/>
      </geometry>
    </visual>
  </link>
  <gazebo reference="right_steering">
    <material>Gazebo/Grey</material>
  </gazebo>
  <joint name="right_steering_hinge" type="revolute">
    <origin rpy="0 0 0" xyz="0.16 -0.10275 0"/>
    <parent link="chassis"/>
    <child link="right_steering"/>
    <axis xyz="0 0 1"/>
    <limit effort="10" lower="-0.5235987755982988" upper="0.5235987755982988" velocity="100"/>
  </joint>
  <transmission name="right_steering_hinge_transmission" type="SimpleTransmission">
    <type>transmission_interface/SimpleTransmission</type>
    <joint name="right_steering_hinge">
      <hardwareInterface>hardware_interface/EffortJointInterface</hardwareInterface>
    </joint>
    <actuator name="right_steering_hinge_motor">
      <hardwareInterface>hardware_interface/EffortJointInterface</hardwareInterface>
      <mechanicalReduction>1</mechanicalReduction>
    </actuator>
  </transmission>
  <!-- Plugins -->
  <!-- Ackermann drive -->
  <gazebo>
    <plugin filename="libgazebo_ros_ackermann_drive.so" name="ackermann_drive">
      <update_rate>100.0</update_rate>
      <!-- wheels -->
      <front_left_joint>left_wheel_front_hinge</front_left_joint>
      <front_right_joint>right_wheel_front_hinge</front_right_joint>
      <rear_left_joint>left_wheel_back_hinge</rear_left_joint>
      <rear_right_joint>right_wheel_back_hinge</rear_right_joint>
      <left_steering_joint>left_steering_hinge</left_steering_joint>
      <right_steering_joint>right_steering_hinge</right_steering_joint>
      <steering_wheel_joint>steering_wheel_joint</steering_wheel_joint>
      <!-- Max absolute steer angle for tyre in radians-->
      <!-- Any cmd_vel angular z greater than this would be capped -->
      <max_steer>0.5235987755982988</max_steer>
      <!-- Max absolute steering angle of steering wheel -->
      <max_steering_angle>9.250245035569947</max_steering_angle>
      <!-- Max absolute linear speed in m/s -->
      <max_speed>10.0</max_speed>
      <left_steering_pid_gain>5 0 0.3</left_steering_pid_gain>
      <left_steering_i_range>0 0</left_steering_i_range>
      <right_steering_pid_gain>5 0 0.3</right_steering_pid_gain>
      <right_steering_i_range>0 0</right_steering_i_range>
      <linear_velocity_pid_gain>0.5 0 0</linear_velocity_pid_gain>
      <linear_velocity_i_range>0 0</linear_velocity_i_range>
      <!-- output -->
      <publish_odom>true</publish_odom>
      <publish_odom_tf>true</publish_odom_tf>
      <publish_wheel_tf>false</publish_wheel_tf>
      <publish_distance>true</publish_distance>
      <odometry_frame>odom</odometry_frame>
      <robot_base_frame>base_link</robot_base_frame>
      <ros>
        <argument>--ros-args --remap cmd_vel:=cmd_vel</argument>
        <argument>--ros-args --remap odom:=odom</argument>
        <argument>--ros-args --remap distance:=distance</argument>
        <remapping>/tf:=tf</remapping>
      </ros>
    </plugin>
  </gazebo>
  <gazebo>
    <plugin filename="libgazebo_ros_joint_state_publisher.so" name="robot_joint_state">
      <ros>
        <remapping>~/out:=joint_states</remapping>
      </ros>
      <update_rate>100</update_rate>
      <joint_name>left_wheel_front_hinge</joint_name>
      <joint_name>right_wheel_front_hinge</joint_name>
      <joint_name>left_wheel_back_hinge</joint_name>
      <joint_name>right_wheel_back_hinge</joint_name>
      <joint_name>left_steering_hinge</joint_name>
      <joint_name>right_steering_hinge</joint_name>
      <joint_name>steering_wheel_joint</joint_name>
    </plugin>
  </gazebo>
  <!-- IMU -->
  <link name="imu_link">
    <visual>
      <origin rpy="0 0 0" xyz="0 0 0"/>
      <geometry>
        <box size="0.02 0.02 0.02"/>
      </geometry>
      <material name="blue"/>
    </visual>
  </link>
  <joint name="imu_joint" type="fixed">
    <axis xyz="0 1 0"/>
    <origin rpy="0 0 0" xyz="0 0 0.045000000000000005"/>
    <parent link="chassis"/>
    <child link="imu_link"/>
  </joint>
  <!-- IMU Sensor -->
  <gazebo reference="imu_link">
    <material>Gazebo/Blue</material>
    <sensor name="imu_sensor" type="imu">
      <plugin filename="libgazebo_ros_imu_sensor.so" name="imu_plugin">
        <ros>
          <namespace>/</namespace>
          <remapping>~/out:=imu</remapping>
        </ros>
        <initial_orientation_as_reference>false</initial_orientation_as_reference>
      </plugin>
      <always_on>true</always_on>
      <update_rate>100</update_rate>
      <visualize>true</visualize>
      <imu>
        <angular_velocity>
          <x>
            <noise type="gaussian">
              <mean>0.0</mean>
              <stddev>2e-4</stddev>
              <bias_mean>0.0000075</bias_mean>
              <bias_stddev>0.0000008</bias_stddev>
            </noise>
          </x>
          <y>
            <noise type="gaussian">
              <mean>0.0</mean>
              <stddev>2e-4</stddev>
              <bias_mean>0.0000075</bias_mean>
              <bias_stddev>0.0000008</bias_stddev>
            </noise>
          </y>
          <z>
            <noise type="gaussian">
              <mean>0.0</mean>
              <stddev>2e-4</stddev>
              <bias_mean>0.0000075</bias_mean>
              <bias_stddev>0.0000008</bias_stddev>
            </noise>
          </z>
        </angular_velocity>
        <linear_acceleration>
          <x>
            <noise type="gaussian">
              <mean>0.0</mean>
              <stddev>1.7e-2</stddev>
              <bias_mean>0.1</bias_mean>
              <bias_stddev>0.001</bias_stddev>
            </noise>
          </x>
          <y>
            <noise type="gaussian">
              <mean>0.0</mean>
              <stddev>1.7e-2</stddev>
              <bias_mean>0.1</bias_mean>
              <bias_stddev>0.001</bias_stddev>
            </noise>
          </y>
          <z>
            <noise type="gaussian">
              <mean>0.0</mean>
              <stddev>1.7e-2</stddev>
              <bias_mean>0.1</bias_mean>
              <bias_stddev>0.001</bias_stddev>
            </noise>
          </z>
        </linear_acceleration>
      </imu>
    </sensor>
  </gazebo>
  <!-- Properties -->
  <!-- Hokuyo Laser -->
  <link name="laser_link">
    <inertial>
      <mass value="0.1"/>
      <origin rpy="0 0 0" xyz="0 0 0"/>
      <inertia ixx="0.00016666666666666672" ixy="0" ixz="0" iyy="0.00016666666666666672" iyz="0" izz="0.00016666666666666672"/>
    </inertial>
    <collision>
      <origin rpy="0 0 0" xyz="0 0 0"/>
      <geometry>
        <box size="0.1 0.1 0.1"/>
      </geometry>
    </collision>
    <visual>
      <origin rpy="0 0 0" xyz="0 0 0"/>
      <geometry>
        <box size="0.1 0.1 0.1"/>
      </geometry>
      <material name="blue"/>
    </visual>
  </link>
  <joint name="laser_joint" type="fixed">
    <axis xyz="0 1 0"/>
    <origin rpy="0 0 0" xyz="0.0 0 0.07"/>
    <parent link="imu_link"/>
    <child link="laser_link"/>
  </joint>
  <!-- Laser Sensor -->
  <gazebo reference="laser_link">
    <material>Gazebo/Blue</material>
    <sensor name="laser_sensor" type="ray">
      <always_on>true</always_on>
      <visualize>true</visualize>
      <update_rate>5</update_rate>
      <pose>0 0 0.075 0 0 0</pose>
      <ray>
        <scan>
          <horizontal>
            <samples>360</samples>
            <resolution>1.000000</resolution>
            <min_angle>0.000000</min_angle>
            <max_angle>6.280000</max_angle>
          </horizontal>
        </scan>
        <range>
          <min>0.120000</min>
          <max>3.5</max>
          <resolution>0.015000</resolution>
        </range>
        <noise>
          <type>gaussian</type>
          <mean>0.0</mean>
          <stddev>0.01</stddev>
        </noise>
      </ray>
      <plugin filename="libgazebo_ros_ray_sensor.so" name="laserscan">
        <ros>
          <!-- <namespace>/tb3</namespace> -->
          <remapping>~/out:=scan</remapping>
        </ros>
        <output_type>sensor_msgs/LaserScan</output_type>
        <frame_name>laser_link</frame_name>
      </plugin>
    </sensor>
  </gazebo>
  <!-- Camera -->
  <link name="camera">
    <inertial>
      <mass value="0.1"/>
      <origin rpy="0 0 0" xyz="0 0 0"/>
      <inertia ixx="0.0002483333333333334" ixy="0" ixz="0" iyy="1.5e-05" iyz="0" izz="0.0002483333333333334"/>
    </inertial>
    <collision>
      <origin rpy="0 0 0" xyz="0 0 0"/>
      <geometry>
        <box size="0.03 0.17 0.03"/>
      </geometry>
    </collision>
    <visual>
      <origin rpy="0 0 0" xyz="0 0 0"/>
      <geometry>
        <box size="0.03 0.17 0.03"/>
      </geometry>
      <material name="red"/>
    </visual>
  </link>
  <joint name="camera_joint" type="fixed">
    <axis xyz="0 1 0"/>
    <origin rpy="0 0 0" xyz="0.16 0 0.05"/>
    <parent link="chassis"/>
    <child link="camera"/>
  </joint>
  <!-- Camera -->
  <gazebo reference="camera">
    <material>Gazebo/Red</material>
    <sensor name="camera" type="camera">
      <visualize>0</visualize>
      <update_rate>30</update_rate>
      <camera name="head">
        <horizontal_fov>1.3962634</horizontal_fov>
        <image>
          <width>800</width>
          <height>800</height>
          <format>R8G8B8</format>
        </image>
        <clip>
          <near>0.02</near>
          <far>300</far>
        </clip>
      </camera>
      <plugin filename="libgazebo_ros_camera.so" name="camera_controller">
        <alwaysOn>true</alwaysOn>
        <updateRate>0.0</updateRate>
        <cameraName>camera</cameraName>
        <imageTopicName>image_raw</imageTopicName>
        <cameraInfoTopicName>camera_info</cameraInfoTopicName>
        <frameName>camera_link</frameName>
        <hackBaseline>0.07</hackBaseline>
        <distortionK1>0.0</distortionK1>
        <distortionK2>0.0</distortionK2>
        <distortionK3>0.0</distortionK3>
        <distortionT1>0.0</distortionT1>
        <distortionT2>0.0</distortionT2>
      </plugin>
    </sensor>
  </gazebo>
</robot>
